Workbook

Sheet Loan_Data
A1: Loan_ID | B1: Customer_Name | C1: Age | D1: Gender | E1: County | F1: Employment_Status | G1: Employment_Length_Years | H1: Annual_Income_KES | I1: Loan_Amount_KES | J1: Interest_Rate_Percent | K1: Loan_Term_Months | L1: Loan_Purpose | M1: Credit_Score | N1: Num_Late_Payments | O1: Loan_Status | P1: Issue_Date | Q1: Debt_To_Income_Ratio
A2: LN-00202 | B2: Carl West | C2: 3 | D2: Male | E2: Nakuru | F2: Business Owner | G2: 7 | H2: 1777690 | I2: 49336 | J2: 11.45 | K2: 48 | L2: Medical | M2: 417 | N2: 4 | O2: Late (31-60 days) | P2: 2020-12-04 | Q2: 0.0278 | T2: Median Age
A3: LN-00686 | B3: Misty Anderson | C3: 42 | D3: Male | E3: Kisumu | F3: Employed | G3: 11 | H3: 1608080 | I3: 639064 | J3: 12.18 | K3: 12 | L3: Personal | M3: 303 | N3: 0 | O3: Fully Paid | P3: 2022-05-08 | Q3: 0.3974
A4: LN-01423 | B4: Albert Bailey | C4: 59 | D4: FEMALE | E4: Machakos | G4: 26 | H4: 1342189 | I4: 694174 | J4: 25.16 | K4: 36 | L4: Medical | M4: 676 | N4: 1 | O4: Fully Paid | P4: 2023-11-05 | Q4: 0.5172
A5: LN-01136 | B5: Emily Barnes | C5: 21 | D5: Female | E5: Kisumu | F5: Self-Employed | G5: 15 | H5: 645982 | I5: 104811 | J5: 22.48 | K5: 24 | M5: 591 | N5: 6 | O5: Late (31-60 days) | P5: 2021-01-25 | Q5: 0.1623
A6: LN-00479 | B6: Troy Carrillo IV | C6: 21 | D6: Female | E6: Thika | F6: Self-Employed | G6: 11 | H6: -1386861 | I6: 667096 | J6: 19.51 | K6: 12 | L6: Home Improvement | M6: 786 | N6: 0 | O6: Current | P6: 31 Jul 2022 | Q6: 0.481
A7: LN-00680 | B7: Gerald Mason | C7: 38 | D7: Female | E7: Kakamega | F7: Business Owner | G7: 28 | H7: 2036231 | I7: 567219 | J7: 16.03 | K7: 60 | L7: Medical | M7: 820 | N7: 2 | O7: Fully Paid | P7: 2022-02-18 | Q7: 0.2786
A8: LN-01257 | B8: George Bass | C8: 41 | D8: Male | E8: Nakuru | F8: Employed | G8: 27 | H8: 1266787 | I8: 614302 | J8: 14.85 | K8: 36 | L8: Business | M8: 441 | N8: 3 | O8: Current | P8: 2021-04-20 | Q8: 0.4849
A9: LN-00161 | B9: Tyler Gillespie | C9: 8 | D9: Female | E9: Machakos | F9: Self-Employed | G9: 4 | H9: 2061175 | I9: 153172 | J9: 14.84 | K9: 24 | L9: Medical | M9: 402 | N9: 5 | O9: Current | P9: 2020-11-19 | Q9: 0.0743
A10: LN-00499 | B10: Robert Randall | C10: 54 | D10: Male | E10: Thika | F10: Self-Employed | G10: 27 | H10: 874892 | I10: 733087 | J10: 17.31 | K10: 60 | L10: Medical | M10: 766 | N10: 7 | O10: Charged Off | P10: 2020-02-26 | Q10: 0.8379
A11: LN-01250 | B11: Nancy Fields | C11: 49 | D11: Male | E11: Kakamega | F11: Unemployed | G11: 16 | H11: 827341 | I11: 798754 | J11: 26.96 | K11: 24 | L11: Agriculture | M11: 840 | N11: 3 | O11: Fully Paid | P11: 2022-02-22 | Q11: 0.9654
A12: LN-01413 | B12: Paul Williams | C12: 55 | D12: Male | E12: Nyeri | F12: Business Owner | G12: 24 | H12: 1596953 | I12: 523323 | J12: 16.61 | K12: 48 | L12: Medical | M12: 644 | N12: 5 | O12: Late (31-60 days) | P12: 2021-07-26 | Q12: 0.3277
A13: LN-00087 | B13: Michael Mckee | C13: 21 | D13: Male | E13: Kisumu | F13: Unemployed | G13: 11 | H13: 1141568 | I13: 118538 | J13: 12.74 | K13: 60 | M13: 306 | N13: 1 | O13: Fully Paid | P13: 2023-07-24 | Q13: 0.1038
A14: LN-01498 | B14: Ashley Stout | C14: 48 | D14: Male | E14: Nairobi | F14: Employed | G14: 23 | H14: 2043462 | I14: 546169 | J14: 8.9 | K14: 60 | L14: Home Improvement | M14: 785 | N14: 3 | O14: Late (61-90 days) | P14: 2020-05-04 | Q14: 0.2673
A15: LN-00308 | B15: Meagan Fernandez | C15: 47 | D15: Male | E15: Mombasa | F15: Self-Employed | G15: 20 | H15: 1387068 | I15: 128042 | J15: 24.88 | K15: 60 | L15: Personal | M15: 813 | N15: 7 | O15: Default | P15: 2022-05-16 | Q15: 0.0923
A16: LN-00663 | B16: Kelly Gomez | C16: 53 | D16: Female | E16: Nyeri | F16: Employed | G16: 2 | H16: 1865996 | I16: 626226 | J16: 16.01 | K16: 36 | L16: Home Improvement | M16: 609 | N16: 2 | O16: Charged Off | P16: 2023-12-17 | Q16: 0.3356
A17: LN-00019 | B17: Shawn Wong DDS | C17: 44 | D17: Male | E17: Thika | F17: Self-Employed | G17: 15 | H17: 2165209 | I17: 687505 | J17: 9.74 | K17: 24 | L17: Medical | M17: 436 | N17: 3 | O17: Late (31-60 days) | P17: 2022-10-31 | Q17: 0.3175
A18: LN-00723 | B18: Casey Hall | C18: 59 | D18: Female | E18: Eldoret | F18: Unemployed | G18: 21 | H18: 809085 | I18: 50949 | J18: 18.33 | K18: 24 | L18: Medical | M18: 302 | N18: 0 | O18: Fully Paid | P18: 2021-03-09 | Q18: 0.063
A19: LN-01231 | B19: Terri Kim | C19: 44 | D19: Female | E19: Machakos | F19: Business Owner | G19: 19 | H19: 1823312 | I19: 221202 | J19: 11.35 | K19: 36 | L19: Education | M19: 488 | N19: 3 | O19: Late (61-90 days) | P19: 2020-02-29 | Q19: 0.1213
A20: LN-00142 | B20: Jennifer Booker | C20: 24 | D20: Female | E20: Thika | F20: Unemployed | G20: 9 | H20: 259083 | I20: 329521 | J20: 23.08 | K20: 24 | L20: Agriculture | M20: 680 | N20: 7 | O20: Current | P20: 2020-05-10 | Q20: 1.2719
A21: LN-00454 | B21: Jamie Savage | C21: 54 | D21: Male | E21: Nakuru | F21: Unemployed | G21: 16 | H21: 741672 | I21: 245391 | J21: 26.69 | K21: 48 | L21: Medical | M21: 552 | N21: 1 | O21: Fully Paid | P21: 2020-07-29 | Q21: 0.3309
A22: LN-01192 | B22: Tiffany Chavez | C22: 36 | D22: Male | E22: Meru | F22: Unemployed | G22: 18 | H22: 1730184 | I22: 176255 | J22: 17.86 | K22: 48 | L22: Business | M22: 422 | N22: 4 | O22: Charged Off | P22: 2020-10-22 | Q22: 0.1019
A23: LN-00330 | B23: Randy Williams | C23: 51 | D23: Male | E23: Nakuru | F23: Business Owner | G23: 1 | H23: 2228891 | I23: 733987 | J23: 20.07 | K23: 60 | L23: Agriculture | M23: 365 | N23: 4 | O23: Fully Paid | P23: 2022-11-06 | Q23: 0.3293
A24: LN-01355 | B24: Michael Herrera | C24: 45 | D24: Female | E24: Eldoret | F24: Employed | G24: 1 | H24: 2152424 | I24: 125686 | J24: 9.03 | K24: 48 | L24: Agriculture | M24: 472 | N24: 3 | O24: Late (61-90 days) | P24: 2022-03-19 | Q24: 0.0584
B25: Leslie Rich | C25: 23 | D25: Female | E25: Thika | F25: Employed | G25: 1 | H25: 368490 | I25: 287247 | J25: 19.07 | K25: 24 | L25: Home Improvement | M25: 403 | N25: 5 | O25: fully paid | P25: 2021-10-08 | Q25: 0.7795
A26: LN-00739 | B26: Robert Sellers MD | C26: 22 | D26: Male | E26: Nakuru | F26: Business Owner | G26: 20 | H26: 1123693 | I26: 393216 | J26: 9.09 | K26: 12 | L26: Business | M26: 498 | N26: 3 | O26: Late (31-60 days) | P26: 2020-05-20 | Q26: 0.3499
A27: LN-00492 | B27: Mark Guerrero | C27: 37 | E27: Nairobi | F27: Self-Employed | G27: 6 | H27: 373510 | I27: 241883 | J27: 24.99 | K27: 24 | L27: Home Improvement | M27: 804 | N27: 2 | O27: Charged Off | P27: 2021-12-20 | Q27: 0.6476
A28: LN-00656 | B28: Austin Joyce | C28: 48 | D28: Male | E28: Kisumu | F28: Unemployed | G28: 14 | H28: 1859161 | I28: 174692 | J28: 14.79 | K28: 60 | L28: Medical | M28: 552 | N28: 5 | O28: Late (31-60 days) | P28: 2020-06-14 | Q28: 0.094
A29: LN-01429 | B29: Sandra Johnson | C29: 30 | D29: Female | E29: Mombasa | F29: Business Owner | G29: 2 | H29: 305438 | I29: 589354 | J29: 18.55 | K29: 60 | L29: Home Improvement | M29: 328 | N29: 6 | O29: Default | P29: 2022-03-26 | Q29: 1.9295
A30: LN-00309 | B30: Brenda Pitts | C30: 54 | D30: Female | E30: Nakuru | F30: Business Owner | G30: 25 | H30: 1702688 | I30: 74110 | J30: 17.68 | K30: 60 | L30: Agriculture | M30: 802 | N30: 6 | O30: Charged Off | P30: 2023-11-27 | Q30: 0.0435
A31: LN-00938 | B31: Christian Douglas | C31: 22 | D31: Female | E31: Machakos | F31: Employed | G31: 1 | H31: 1636081 | I31: 210920 | J31: 19.1 | K31: 24 | L31: Agriculture | M31: 809 | N31: 5 | O31: Charged Off | P31: 2023-11-06 | Q31: 0.1289
A32: LN-00288 | B32: Janet Johnson | C32: 56 | D32: Female | E32: Machakos | F32: Employed | G32: 18 | H32: 1103780 | I32: 515164 | J32: 25.72 | K32: 36 | L32: Home Improvement | M32: 464 | N32: 4 | O32: Fully Paid | P32: 2020-04-13 | Q32: 0.4667
A33: LN-01415 | B33: Samuel Smith | C33: 54 | D33: Male | E33: Meru | F33: Employed | G33: 3 | H33: 601280 | I33: 797635 | J33: 22.13 | K33: 24 | L33: Agriculture | M33: 849 | N33: 2 | O33: Default | P33: 11-14-2023 | Q33: 1.3266
A34: LN-00468 | B34: Joseph Cortez MD | C34: 47 | D34: Female | E34: Thika | F34: Employed | G34: 17 | H34: 691083 | I34: 396087 | J34: 25.31 | K34: 12 | L34: Agriculture | M34: 449 | N34: 6 | O34: Late (61-90 days) | P34: 2023-10-03 | Q34: 0.5731
A35: LN-00448 | B35: Richard Gonzalez | C35: 50 | D35: Female | E35: Nairobi | F35: Business Owner | G35: 6 | H35: 746956 | I35: 407699 | J35: 16.22 | K35: 12 | L35: Agriculture | M35: 725 | N35: 6 | O35: current | P35: 2020-03-22 | Q35: 0.5458
A36: LN-01117 | B36: Steven Hernandez | C36: 27 | D36: Male | E36: Nairobi | F36: Employed | G36: 28 | H36: 656513 | I36: 83972 | J36: 23.04 | K36: 48 | L36: Business | M36: 681 | N36: 6 | O36: Default | P36: 2021-04-05 | Q36: 0.1279
A37: LN-01028 | B37: Scott Pham | C37: 58 | D37: Female | E37: Machakos | F37: Business Owner | G37: 11 | H37: -551616 | I37: 686015 | J37: 26.9 | K37: 48 | L37: Home Improvement | M37: 628 | N37: 1 | O37: Charged Off | P37: 2023-05-09 | Q37: 1.2436
A38: LN-00637 | B38: Matthew Salazar | C38: 23 | D38: Female | E38: Nyeri | F38: Employed | G38: 5 | H38: 1724613 | I38: 425105 | J38: 26.23 | K38: 12 | L38: Business | M38: 596 | N38: 7 | O38: Late (31-60 days) | P38: 2022-08-30 | Q38: 0.2465
A39: LN-00075 | B39: Susan Taylor | C39: 34 | D39: male | E39: Kakamega | F39: Employed | G39: 14 | H39: 777897 | I39: 411858 | J39: 8.99 | K39: 24 | L39: Home Improvement | M39: 552 | N39: 2 | O39: Current | P39: 2022-01-17 | Q39: 0.5295
A40: LN-01481 | B40: Megan Franklin | C40: 38 | D40: Female | E40: Mombasa | F40: Business Owner | G40: 10 | H40: 2287359 | I40: 550875 | J40: 12.73 | K40: 36 | L40: Personal | M40: 714 | N40: 6 | O40: Late (31-60 days) | P40: 2022-09-02 | Q40: 0.2408
...

Sheet Cleaned_Loan_Data
A1: Loan_ID | B1: Helper_Column | C1: Customer_Name | D1: Age | E1: New_Age | F1: Gender | G1: New_Gender | H1: County | I1: Employment_Status | K1: New_Employment_Status | L1: Employment_Length_Years | M1: Annual_Income_KES | N1: New_Annual_Income | O1: Loan_Amount_KES | P1: Interest_Rate_Percent | Q1: Loan_Term_Months | R1: Loan_Purpose | S1: New_Loan_Purpose | T1: Credit_Score | U1: New_Credit_Score | V1: Num_Late_Payments | W1: Loan_Status | X1: Issue_Date | Y1: New_Date | Z1: Debt_To_Income_Ratio | AC1: Med Age | AD1: {=MEDIAN(IF((D2:D1517>=18)*(D2:D1517<=100), D2:D1517))} -> 44
A2: LN-00202 | B2: =IF(A2="", "MISSING", "OK") -> OK | C2: Carl West | D2: 3 | E2: =IF(OR(D2<18, D2>100),AD1,D2) -> 44 | F2: Male | G2: =IF(F2="", "Unknown", IF(OR(F2="F", F2="FEMALE", F2="Female"), "Female", IF(OR(F2="M", F2="MALE", F2="Male"), "Male", "Other"))) -> Male | H2: Nakuru | I2: Business Owner | K2: =IF(I2="", "Unknown", I2) -> Business Owner | L2: 7 | M2: 1777690 | N2: =IF(OR(M2="",M2<0),$AD$3,M2) -> 1777690 | O2: 49336 | P2: 11.45 | Q2: 48 | R2: Medical | S2: =IF(R2="", "Unknown", R2) -> Medical | T2: 417 | U2: =IF(OR(T2="",T2>999),$AD$2,T2) -> 417 | V2: 4 | W2: Late (31-60 days) | X2: 2020-12-04 | Y2: =IF(ISNUMBER(X2), X2, DATEVALUE(X2)) -> 44169 | Z2: 0.0278 | AC2: Med Cred | AD2: {=MEDIAN(IF((T2:T1517>=0)*(T2:T1517<=999),T2:T1517))} -> 556
A3: LN-00686 | B3: =IF(A3="", "MISSING", "OK") -> OK | C3: Misty Anderson | D3: 42 | E3: =IF(OR(D3<18, D3>100),AD2,D3) -> 42 | F3: Male | G3: =IF(F3="", "Unknown", IF(OR(F3="F", F3="FEMALE", F3="Female"), "Female", IF(OR(F3="M", F3="MALE", F3="Male"), "Male", "Other"))) -> Male | H3: Kisumu | I3: Employed | K3: =IF(I3="", "Unknown", I3) -> Employed | L3: 11 | M3: 1608080 | N3: =IF(OR(M3="",M3<0),$AD$3,M3) -> 1608080 | O3: 639064 | P3: 12.18 | Q3: 12 | R3: Personal | S3: =IF(R3="", "Unknown", R3) -> Personal | T3: 303 | U3: =IF(OR(T3="",T3>999),$AD$2,T3) -> 303 | V3: 0 | W3: Fully Paid | X3: 2022-05-08 | Y3: =IF(ISNUMBER(X3), X3, DATEVALUE(X3)) -> 44689 | Z3: 0.3974 | AC3: Med Inc | AD3: {=MEDIAN(IF(M2:M1517>0, M2:M1517))} -> 1333224
A4: LN-01423 | B4: =IF(A4="", "MISSING", "OK") -> OK | C4: Albert Bailey | D4: 59 | E4: =IF(OR(D4<18, D4>100),AD3,D4) -> 59 | F4: FEMALE | G4: =IF(F4="", "Unknown", IF(OR(F4="F", F4="FEMALE", F4="Female"), "Female", IF(OR(F4="M", F4="MALE", F4="Male"), "Male", "Other"))) -> Female | H4: Machakos | K4: =IF(I4="", "Unknown", I4) -> Unknown | L4: 26 | M4: 1342189 | N4: =IF(OR(M4="",M4<0),$AD$3,M4) -> 1342189 | O4: 694174 | P4: 25.16 | Q4: 36 | R4: Medical | S4: =IF(R4="", "Unknown", R4) -> Medical | T4: 676 | U4: =IF(OR(T4="",T4>999),$AD$2,T4) -> 676 | V4: 1 | W4: Fully Paid | X4: 2023-11-05 | Y4: =IF(ISNUMBER(X4), X4, DATEVALUE(X4)) -> 45235 | Z4: 0.5172
A5: LN-01136 | B5: =IF(A5="", "MISSING", "OK") -> OK | C5: Emily Barnes | D5: 21 | E5: =IF(OR(D5<18, D5>100),AD4,D5) -> 21 | F5: Female | G5: =IF(F5="", "Unknown", IF(OR(F5="F", F5="FEMALE", F5="Female"), "Female", IF(OR(F5="M", F5="MALE", F5="Male"), "Male", "Other"))) -> Female | H5: Kisumu | I5: Self-Employed | K5: =IF(I5="", "Unknown", I5) -> Self-Employed | L5: 15 | M5: 645982 | N5: =IF(OR(M5="",M5<0),$AD$3,M5) -> 645982 | O5: 104811 | P5: 22.48 | Q5: 24 | S5: =IF(R5="", "Unknown", R5) -> Unknown | T5: 591 | U5: =IF(OR(T5="",T5>999),$AD$2,T5) -> 591 | V5: 6 | W5: Late (31-60 days) | X5: 2021-01-25 | Y5: =IF(ISNUMBER(X5), X5, DATEVALUE(X5)) -> 44221 | Z5: 0.1623
A6: LN-00479 | B6: =IF(A6="", "MISSING", "OK") -> OK | C6: Troy Carrillo IV | D6: 21 | E6: =IF(OR(D6<18, D6>100),AD5,D6) -> 21 | F6: Female | G6: =IF(F6="", "Unknown", IF(OR(F6="F", F6="FEMALE", F6="Female"), "Female", IF(OR(F6="M", F6="MALE", F6="Male"), "Male", "Other"))) -> Female | H6: Thika | I6: Self-Employed | K6: =IF(I6="", "Unknown", I6) -> Self-Employed | L6: 11 | M6: -1386861 | N6: =IF(OR(M6="",M6<0),$AD$3,M6) -> 1333224 | O6: 667096 | P6: 19.51 | Q6: 12 | R6: Home Improvement | S6: =IF(R6="", "Unknown", R6) -> Home Improvement | T6: 786 | U6: =IF(OR(T6="",T6>999),$AD$2,T6) -> 786 | V6: 0 | W6: Current | X6: 44773 | Y6: =IF(ISNUMBER(X6), X6, DATEVALUE(X6)) -> 44773 | Z6: 0.481
A7: LN-00680 | B7: =IF(A7="", "MISSING", "OK") -> OK | C7: Gerald Mason | D7: 38 | E7: =IF(OR(D7<18, D7>100),AD6,D7) -> 38 | F7: Female | G7: =IF(F7="", "Unknown", IF(OR(F7="F", F7="FEMALE", F7="Female"), "Female", IF(OR(F7="M", F7="MALE", F7="Male"), "Male", "Other"))) -> Female | H7: Kakamega | I7: Business Owner | K7: =IF(I7="", "Unknown", I7) -> Business Owner | L7: 28 | M7: 2036231 | N7: =IF(OR(M7="",M7<0),$AD$3,M7) -> 2036231 | O7: 567219 | P7: 16.03 | Q7: 60 | R7: Medical | S7: =IF(R7="", "Unknown", R7) -> Medical | T7: 820 | U7: =IF(OR(T7="",T7>999),$AD$2,T7) -> 820 | V7: 2 | W7: Fully Paid | X7: 2022-02-18 | Y7: =IF(ISNUMBER(X7), X7, DATEVALUE(X7)) -> 44610 | Z7: 0.2786
A8: LN-01257 | B8: =IF(A8="", "MISSING", "OK") -> OK | C8: George Bass | D8: 41 | E8: =IF(OR(D8<18, D8>100),AD7,D8) -> 41 | F8: Male | G8: =IF(F8="", "Unknown", IF(OR(F8="F", F8="FEMALE", F8="Female"), "Female", IF(OR(F8="M", F8="MALE", F8="Male"), "Male", "Other"))) -> Male | H8: Nakuru | I8: Employed | K8: =IF(I8="", "Unknown", I8) -> Employed | L8: 27 | M8: 1266787 | N8: =IF(OR(M8="",M8<0),$AD$3,M8) -> 1266787 | O8: 614302 | P8: 14.85 | Q8: 36 | R8: Business | S8: =IF(R8="", "Unknown", R8) -> Business | T8: 441 | U8: =IF(OR(T8="",T8>999),$AD$2,T8) -> 441 | V8: 3 | W8: Current | X8: 2021-04-20 | Y8: =IF(ISNUMBER(X8), X8, DATEVALUE(X8)) -> 44306 | Z8: 0.4849
A9: LN-00161 | B9: =IF(A9="", "MISSING", "OK") -> OK | C9: Tyler Gillespie | D9: 8 | E9: =IF(OR(D9<18, D9>100),AD8,D9) -> 0 | F9: Female | G9: =IF(F9="", "Unknown", IF(OR(F9="F", F9="FEMALE", F9="Female"), "Female", IF(OR(F9="M", F9="MALE", F9="Male"), "Male", "Other"))) -> Female | H9: Machakos | I9: Self-Employed | K9: =IF(I9="", "Unknown", I9) -> Self-Employed | L9: 4 | M9: 2061175 | N9: =IF(OR(M9="",M9<0),$AD$3,M9) -> 2061175 | O9: 153172 | P9: 14.84 | Q9: 24 | R9: Medical | S9: =IF(R9="", "Unknown", R9) -> Medical | T9: 402 | U9: =IF(OR(T9="",T9>999),$AD$2,T9) -> 402 | V9: 5 | W9: Current | X9: 2020-11-19 | Y9: =IF(ISNUMBER(X9), X9, DATEVALUE(X9)) -> 44154 | Z9: 0.0743
A10: LN-00499 | B10: =IF(A10="", "MISSING", "OK") -> OK | C10: Robert Randall | D10: 54 | E10: =IF(OR(D10<18, D10>100),AD9,D10) -> 54 | F10: Male | G10: =IF(F10="", "Unknown", IF(OR(F10="F", F10="FEMALE", F10="Female"), "Female", IF(OR(F10="M", F10="MALE", F10="Male"), "Male", "Other"))) -> Male | H10: Thika | I10: Self-Employed | K10: =IF(I10="", "Unknown", I10) -> Self-Employed | L10: 27 | M10: 874892 | N10: =IF(OR(M10="",M10<0),$AD$3,M10) -> 874892 | O10: 733087 | P10: 17.31 | Q10: 60 | R10: Medical | S10: =IF(R10="", "Unknown", R10) -> Medical | T10: 766 | U10: =IF(OR(T10="",T10>999),$AD$2,T10) -> 766 | V10: 7 | W10: Charged Off | X10: 2020-02-26 | Y10: =IF(ISNUMBER(X10), X10, DATEVALUE(X10)) -> 43887 | Z10: 0.8379
A11: LN-01250 | B11: =IF(A11="", "MISSING", "OK") -> OK | C11: Nancy Fields | D11: 49 | E11: =IF(OR(D11<18, D11>100),AD10,D11) -> 49 | F11: Male | G11: =IF(F11="", "Unknown", IF(OR(F11="F", F11="FEMALE", F11="Female"), "Female", IF(OR(F11="M", F11="MALE", F11="Male"), "Male", "Other"))) -> Male | H11: Kakamega | I11: Unemployed | K11: =IF(I11="", "Unknown", I11) -> Unemployed | L11: 16 | M11: 827341 | N11: =IF(OR(M11="",M11<0),$AD$3,M11) -> 827341 | O11: 798754 | P11: 26.96 | Q11: 24 | R11: Agriculture | S11: =IF(R11="", "Unknown", R11) -> Agriculture | T11: 840 | U11: =IF(OR(T11="",T11>999),$AD$2,T11) -> 840 | V11: 3 | W11: Fully Paid | X11: 2022-02-22 | Y11: =IF(ISNUMBER(X11), X11, DATEVALUE(X11)) -> 44614 | Z11: 0.9654
A12: LN-01413 | B12: =IF(A12="", "MISSING", "OK") -> OK | C12: Paul Williams | D12: 55 | E12: =IF(OR(D12<18, D12>100),AD11,D12) -> 55 | F12: Male | G12: =IF(F12="", "Unknown", IF(OR(F12="F", F12="FEMALE", F12="Female"), "Female", IF(OR(F12="M", F12="MALE", F12="Male"), "Male", "Other"))) -> Male | H12: Nyeri | I12: Business Owner | K12: =IF(I12="", "Unknown", I12) -> Business Owner | L12: 24 | M12: 1596953 | N12: =IF(OR(M12="",M12<0),$AD$3,M12) -> 1596953 | O12: 523323 | P12: 16.61 | Q12: 48 | R12: Medical | S12: =IF(R12="", "Unknown", R12) -> Medical | T12: 644 | U12: =IF(OR(T12="",T12>999),$AD$2,T12) -> 644 | V12: 5 | W12: Late (31-60 days) | X12: 2021-07-26 | Y12: =IF(ISNUMBER(X12), X12, DATEVALUE(X12)) -> 44403 | Z12: 0.3277
A13: LN-00087 | B13: =IF(A13="", "MISSING", "OK") -> OK | C13: Michael Mckee | D13: 21 | E13: =IF(OR(D13<18, D13>100),AD12,D13) -> 21 | F13: Male | G13: =IF(F13="", "Unknown", IF(OR(F13="F", F13="FEMALE", F13="Female"), "Female", IF(OR(F13="M", F13="MALE", F13="Male"), "Male", "Other"))) -> Male | H13: Kisumu | I13: Unemployed | K13: =IF(I13="", "Unknown", I13) -> Unemployed | L13: 11 | M13: 1141568 | N13: =IF(OR(M13="",M13<0),$AD$3,M13) -> 1141568 | O13: 118538 | P13: 12.74 | Q13: 60 | S13: =IF(R13="", "Unknown", R13) -> Unknown | T13: 306 | U13: =IF(OR(T13="",T13>999),$AD$2,T13) -> 306 | V13: 1 | W13: Fully Paid | X13: 2023-07-24 | Y13: =IF(ISNUMBER(X13), X13, DATEVALUE(X13)) -> 45131 | Z13: 0.1038
A14: LN-01498 | B14: =IF(A14="", "MISSING", "OK") -> OK | C14: Ashley Stout | D14: 48 | E14: =IF(OR(D14<18, D14>100),AD13,D14) -> 48 | F14: Male | G14: =IF(F14="", "Unknown", IF(OR(F14="F", F14="FEMALE", F14="Female"), "Female", IF(OR(F14="M", F14="MALE", F14="Male"), "Male", "Other"))) -> Male | H14: Nairobi | I14: Employed | K14: =IF(I14="", "Unknown", I14) -> Employed | L14: 23 | M14: 2043462 | N14: =IF(OR(M14="",M14<0),$AD$3,M14) -> 2043462 | O14: 546169 | P14: 8.9 | Q14: 60 | R14: Home Improvement | S14: =IF(R14="", "Unknown", R14) -> Home Improvement | T14: 785 | U14: =IF(OR(T14="",T14>999),$AD$2,T14) -> 785 | V14: 3 | W14: Late (61-90 days) | X14: 2020-05-04 | Y14: =IF(ISNUMBER(X14), X14, DATEVALUE(X14)) -> 43955 | Z14: 0.2673
A15: LN-00308 | B15: =IF(A15="", "MISSING", "OK") -> OK | C15: Meagan Fernandez | D15: 47 | E15: =IF(OR(D15<18, D15>100),AD14,D15) -> 47 | F15: Male | G15: =IF(F15="", "Unknown", IF(OR(F15="F", F15="FEMALE", F15="Female"), "Female", IF(OR(F15="M", F15="MALE", F15="Male"), "Male", "Other"))) -> Male | H15: Mombasa | I15: Self-Employed | K15: =IF(I15="", "Unknown", I15) -> Self-Employed | L15: 20 | M15: 1387068 | N15: =IF(OR(M15="",M15<0),$AD$3,M15) -> 1387068 | O15: 128042 | P15: 24.88 | Q15: 60 | R15: Personal | S15: =IF(R15="", "Unknown", R15) -> Personal | T15: 813 | U15: =IF(OR(T15="",T15>999),$AD$2,T15) -> 813 | V15: 7 | W15: Default | X15: 2022-05-16 | Y15: =IF(ISNUMBER(X15), X15, DATEVALUE(X15)) -> 44697 | Z15: 0.0923
A16: LN-00663 | B16: =IF(A16="", "MISSING", "OK") -> OK | C16: Kelly Gomez | D16: 53 | E16: =IF(OR(D16<18, D16>100),AD15,D16) -> 53 | F16: Female | G16: =IF(F16="", "Unknown", IF(OR(F16="F", F16="FEMALE", F16="Female"), "Female", IF(OR(F16="M", F16="MALE", F16="Male"), "Male", "Other"))) -> Female | H16: Nyeri | I16: Employed | K16: =IF(I16="", "Unknown", I16) -> Employed | L16: 2 | M16: 1865996 | N16: =IF(OR(M16="",M16<0),$AD$3,M16) -> 1865996 | O16: 626226 | P16: 16.01 | Q16: 36 | R16: Home Improvement | S16: =IF(R16="", "Unknown", R16) -> Home Improvement | T16: 609 | U16: =IF(OR(T16="",T16>999),$AD$2,T16) -> 609 | V16: 2 | W16: Charged Off | X16: 2023-12-17 | Y16: =IF(ISNUMBER(X16), X16, DATEVALUE(X16)) -> 45277 | Z16: 0.3356
A17: LN-00019 | B17: =IF(A17="", "MISSING", "OK") -> OK | C17: Shawn Wong DDS | D17: 44 | E17: =IF(OR(D17<18, D17>100),AD16,D17) -> 44 | F17: Male | G17: =IF(F17="", "Unknown", IF(OR(F17="F", F17="FEMALE", F17="Female"), "Female", IF(OR(F17="M", F17="MALE", F17="Male"), "Male", "Other"))) -> Male | H17: Thika | I17: Self-Employed | K17: =IF(I17="", "Unknown", I17) -> Self-Employed | L17: 15 | M17: 2165209 | N17: =IF(OR(M17="",M17<0),$AD$3,M17) -> 2165209 | O17: 687505 | P17: 9.74 | Q17: 24 | R17: Medical | S17: =IF(R17="", "Unknown", R17) -> Medical | T17: 436 | U17: =IF(OR(T17="",T17>999),$AD$2,T17) -> 436 | V17: 3 | W17: Late (31-60 days) | X17: 2022-10-31 | Y17: =IF(ISNUMBER(X17), X17, DATEVALUE(X17)) -> 44865 | Z17: 0.3175
A18: LN-00723 | B18: =IF(A18="", "MISSING", "OK") -> OK | C18: Casey Hall | D18: 59 | E18: =IF(OR(D18<18, D18>100),AD17,D18) -> 59 | F18: Female | G18: =IF(F18="", "Unknown", IF(OR(F18="F", F18="FEMALE", F18="Female"), "Female", IF(OR(F18="M", F18="MALE", F18="Male"), "Male", "Other"))) -> Female | H18: Eldoret | I18: Unemployed | K18: =IF(I18="", "Unknown", I18) -> Unemployed | L18: 21 | M18: 809085 | N18: =IF(OR(M18="",M18<0),$AD$3,M18) -> 809085 | O18: 50949 | P18: 18.33 | Q18: 24 | R18: Medical | S18: =IF(R18="", "Unknown", R18) -> Medical | T18: 302 | U18: =IF(OR(T18="",T18>999),$AD$2,T18) -> 302 | V18: 0 | W18: Fully Paid | X18: 2021-03-09 | Y18: =IF(ISNUMBER(X18), X18, DATEVALUE(X18)) -> 44264 | Z18: 0.063
A19: LN-01231 | B19: =IF(A19="", "MISSING", "OK") -> OK | C19: Terri Kim | D19: 44 | E19: =IF(OR(D19<18, D19>100),AD18,D19) -> 44 | F19: Female | G19: =IF(F19="", "Unknown", IF(OR(F19="F", F19="FEMALE", F19="Female"), "Female", IF(OR(F19="M", F19="MALE", F19="Male"), "Male", "Other"))) -> Female | H19: Machakos | I19: Business Owner | K19: =IF(I19="", "Unknown", I19) -> Business Owner | L19: 19 | M19: 1823312 | N19: =IF(OR(M19="",M19<0),$AD$3,M19) -> 1823312 | O19: 221202 | P19: 11.35 | Q19: 36 | R19: Education | S19: =IF(R19="", "Unknown", R19) -> Education | T19: 488 | U19: =IF(OR(T19="",T19>999),$AD$2,T19) -> 488 | V19: 3 | W19: Late (61-90 days) | X19: 2020-02-29 | Y19: =IF(ISNUMBER(X19), X19, DATEVALUE(X19)) -> 43890 | Z19: 0.1213
A20: LN-00142 | B20: =IF(A20="", "MISSING", "OK") -> OK | C20: Jennifer Booker | D20: 24 | E20: =IF(OR(D20<18, D20>100),AD19,D20) -> 24 | F20: Female | G20: =IF(F20="", "Unknown", IF(OR(F20="F", F20="FEMALE", F20="Female"), "Female", IF(OR(F20="M", F20="MALE", F20="Male"), "Male", "Other"))) -> Female | H20: Thika | I20: Unemployed | K20: =IF(I20="", "Unknown", I20) -> Unemployed | L20: 9 | M20: 259083 | N20: =IF(OR(M20="",M20<0),$AD$3,M20) -> 259083 | O20: 329521 | P20: 23.08 | Q20: 24 | R20: Agriculture | S20: =IF(R20="", "Unknown", R20) -> Agriculture | T20: 680 | U20: =IF(OR(T20="",T20>999),$AD$2,T20) -> 680 | V20: 7 | W20: Current | X20: 2020-05-10 | Y20: =IF(ISNUMBER(X20), X20, DATEVALUE(X20)) -> 43961 | Z20: 1.2719
A21: LN-00454 | B21: =IF(A21="", "MISSING", "OK") -> OK | C21: Jamie Savage | D21: 54 | E21: =IF(OR(D21<18, D21>100),AD20,D21) -> 54 | F21: Male | G21: =IF(F21="", "Unknown", IF(OR(F21="F", F21="FEMALE", F21="Female"), "Female", IF(OR(F21="M", F21="MALE", F21="Male"), "Male", "Other"))) -> Male | H21: Nakuru | I21: Unemployed | K21: =IF(I21="", "Unknown", I21) -> Unemployed | L21: 16 | M21: 741672 | N21: =IF(OR(M21="",M21<0),$AD$3,M21) -> 741672 | O21: 245391 | P21: 26.69 | Q21: 48 | R21: Medical | S21: =IF(R21="", "Unknown", R21) -> Medical | T21: 552 | U21: =IF(OR(T21="",T21>999),$AD$2,T21) -> 552 | V21: 1 | W21: Fully Paid | X21: 2020-07-29 | Y21: =IF(ISNUMBER(X21), X21, DATEVALUE(X21)) -> 44041 | Z21: 0.3309
A22: LN-01192 | B22: =IF(A22="", "MISSING", "OK") -> OK | C22: Tiffany Chavez | D22: 36 | E22: =IF(OR(D22<18, D22>100),AD21,D22) -> 36 | F22: Male | G22: =IF(F22="", "Unknown", IF(OR(F22="F", F22="FEMALE", F22="Female"), "Female", IF(OR(F22="M", F22="MALE", F22="Male"), "Male", "Other"))) -> Male | H22: Meru | I22: Unemployed | K22: =IF(I22="", "Unknown", I22) -> Unemployed | L22: 18 | M22: 1730184 | N22: =IF(OR(M22="",M22<0),$AD$3,M22) -> 1730184 | O22: 176255 | P22: 17.86 | Q22: 48 | R22: Business | S22: =IF(R22="", "Unknown", R22) -> Business | T22: 422 | U22: =IF(OR(T22="",T22>999),$AD$2,T22) -> 422 | V22: 4 | W22: Charged Off | X22: 2020-10-22 | Y22: =IF(ISNUMBER(X22), X22, DATEVALUE(X22)) -> 44126 | Z22: 0.1019
A23: LN-00330 | B23: =IF(A23="", "MISSING", "OK") -> OK | C23: Randy Williams | D23: 51 | E23: =IF(OR(D23<18, D23>100),AD22,D23) -> 51 | F23: Male | G23: =IF(F23="", "Unknown", IF(OR(F23="F", F23="FEMALE", F23="Female"), "Female", IF(OR(F23="M", F23="MALE", F23="Male"), "Male", "Other"))) -> Male | H23: Nakuru | I23: Business Owner | K23: =IF(I23="", "Unknown", I23) -> Business Owner | L23: 1 | M23: 2228891 | N23: =IF(OR(M23="",M23<0),$AD$3,M23) -> 2228891 | O23: 733987 | P23: 20.07 | Q23: 60 | R23: Agriculture | S23: =IF(R23="", "Unknown", R23) -> Agriculture | T23: 365 | U23: =IF(OR(T23="",T23>999),$AD$2,T23) -> 365 | V23: 4 | W23: Fully Paid | X23: 2022-11-06 | Y23: =IF(ISNUMBER(X23), X23, DATEVALUE(X23)) -> 44871 | Z23: 0.3293
A24: LN-01355 | B24: =IF(A24="", "MISSING", "OK") -> OK | C24: Michael Herrera | D24: 45 | E24: =IF(OR(D24<18, D24>100),AD23,D24) -> 45 | F24: Female | G24: =IF(F24="", "Unknown", IF(OR(F24="F", F24="FEMALE", F24="Female"), "Female", IF(OR(F24="M", F24="MALE", F24="Male"), "Male", "Other"))) -> Female | H24: Eldoret | I24: Employed | K24: =IF(I24="", "Unknown", I24) -> Employed | L24: 1 | M24: 2152424 | N24: =IF(OR(M24="",M24<0),$AD$3,M24) -> 2152424 | O24: 125686 | P24: 9.03 | Q24: 48 | R24: Agriculture | S24: =IF(R24="", "Unknown", R24) -> Agriculture | T24: 472 | U24: =IF(OR(T24="",T24>999),$AD$2,T24) -> 472 | V24: 3 | W24: Late (61-90 days) | X24: 2022-03-19 | Y24: =IF(ISNUMBER(X24), X24, DATEVALUE(X24)) -> 44639 | Z24: 0.0584
A25: LN-00739 | B25: =IF(A25="", "MISSING", "OK") -> OK | C25: Robert Sellers MD | D25: 22 | E25: =IF(OR(D25<18, D25>100),AD24,D25) -> 22 | F25: Male | G25: =IF(F25="", "Unknown", IF(OR(F25="F", F25="FEMALE", F25="Female"), "Female", IF(OR(F25="M", F25="MALE", F25="Male"), "Male", "Other"))) -> Male | H25: Nakuru | I25: Business Owner | K25: =IF(I25="", "Unknown", I25) -> Business Owner | L25: 20 | M25: 1123693 | N25: =IF(OR(M25="",M25<0),$AD$3,M25) -> 1123693 | O25: 393216 | P25: 9.09 | Q25: 12 | R25: Business | S25: =IF(R25="", "Unknown", R25) -> Business | T25: 498 | U25: =IF(OR(T25="",T25>999),$AD$2,T25) -> 498 | V25: 3 | W25: Late (31-60 days) | X25: 2020-05-20 | Y25: =IF(ISNUMBER(X25), X25, DATEVALUE(X25)) -> 43971 | Z25: 0.3499
A26: LN-00492 | B26: =IF(A26="", "MISSING", "OK") -> OK | C26: Mark Guerrero | D26: 37 | E26: =IF(OR(D26<18, D26>100),AD25,D26) -> 37 | G26: =IF(F26="", "Unknown", IF(OR(F26="F", F26="FEMALE", F26="Female"), "Female", IF(OR(F26="M", F26="MALE", F26="Male"), "Male", "Other"))) -> Unknown | H26: Nairobi | I26: Self-Employed | K26: =IF(I26="", "Unknown", I26) -> Self-Employed | L26: 6 | M26: 373510 | N26: =IF(OR(M26="",M26<0),$AD$3,M26) -> 373510 | O26: 241883 | P26: 24.99 | Q26: 24 | R26: Home Improvement | S26: =IF(R26="", "Unknown", R26) -> Home Improvement | T26: 804 | U26: =IF(OR(T26="",T26>999),$AD$2,T26) -> 804 | V26: 2 | W26: Charged Off | X26: 2021-12-20 | Y26: =IF(ISNUMBER(X26), X26, DATEVALUE(X26)) -> 44550 | Z26: 0.6476
A27: LN-00656 | B27: =IF(A27="", "MISSING", "OK") -> OK | C27: Austin Joyce | D27: 48 | E27: =IF(OR(D27<18, D27>100),AD26,D27) -> 48 | F27: Male | G27: =IF(F27="", "Unknown", IF(OR(F27="F", F27="FEMALE", F27="Female"), "Female", IF(OR(F27="M", F27="MALE", F27="Male"), "Male", "Other"))) -> Male | H27: Kisumu | I27: Unemployed | K27: =IF(I27="", "Unknown", I27) -> Unemployed | L27: 14 | M27: 1859161 | N27: =IF(OR(M27="",M27<0),$AD$3,M27) -> 1859161 | O27: 174692 | P27: 14.79 | Q27: 60 | R27: Medical | S27: =IF(R27="", "Unknown", R27) -> Medical | T27: 552 | U27: =IF(OR(T27="",T27>999),$AD$2,T27) -> 552 | V27: 5 | W27: Late (31-60 days) | X27: 2020-06-14 | Y27: =IF(ISNUMBER(X27), X27, DATEVALUE(X27)) -> 43996 | Z27: 0.094
A28: LN-01429 | B28: =IF(A28="", "MISSING", "OK") -> OK | C28: Sandra Johnson | D28: 30 | E28: =IF(OR(D28<18, D28>100),AD27,D28) -> 30 | F28: Female | G28: =IF(F28="", "Unknown", IF(OR(F28="F", F28="FEMALE", F28="Female"), "Female", IF(OR(F28="M", F28="MALE", F28="Male"), "Male", "Other"))) -> Female | H28: Mombasa | I28: Business Owner | K28: =IF(I28="", "Unknown", I28) -> Business Owner | L28: 2 | M28: 305438 | N28: =IF(OR(M28="",M28<0),$AD$3,M28) -> 305438 | O28: 589354 | P28: 18.55 | Q28: 60 | R28: Home Improvement | S28: =IF(R28="", "Unknown", R28) -> Home Improvement | T28: 328 | U28: =IF(OR(T28="",T28>999),$AD$2,T28) -> 328 | V28: 6 | W28: Default | X28: 2022-03-26 | Y28: =IF(ISNUMBER(X28), X28, DATEVALUE(X28)) -> 44646 | Z28: 1.9295
A29: LN-00309 | B29: =IF(A29="", "MISSING", "OK") -> OK | C29: Brenda Pitts | D29: 54 | E29: =IF(OR(D29<18, D29>100),AD28,D29) -> 54 | F29: Female | G29: =IF(F29="", "Unknown", IF(OR(F29="F", F29="FEMALE", F29="Female"), "Female", IF(OR(F29="M", F29="MALE", F29="Male"), "Male", "Other"))) -> Female | H29: Nakuru | I29: Business Owner | K29: =IF(I29="", "Unknown", I29) -> Business Owner | L29: 25 | M29: 1702688 | N29: =IF(OR(M29="",M29<0),$AD$3,M29) -> 1702688 | O29: 74110 | P29: 17.68 | Q29: 60 | R29: Agriculture | S29: =IF(R29="", "Unknown", R29) -> Agriculture | T29: 802 | U29: =IF(OR(T29="",T29>999),$AD$2,T29) -> 802 | V29: 6 | W29: Charged Off | X29: 2023-11-27 | Y29: =IF(ISNUMBER(X29), X29, DATEVALUE(X29)) -> 45257 | Z29: 0.0435
A30: LN-00938 | B30: =IF(A30="", "MISSING", "OK") -> OK | C30: Christian Douglas | D30: 22 | E30: =IF(OR(D30<18, D30>100),AD29,D30) -> 22 | F30: Female | G30: =IF(F30="", "Unknown", IF(OR(F30="F", F30="FEMALE", F30="Female"), "Female", IF(OR(F30="M", F30="MALE", F30="Male"), "Male", "Other"))) -> Female | H30: Machakos | I30: Employed | K30: =IF(I30="", "Unknown", I30) -> Employed | L30: 1 | M30: 1636081 | N30: =IF(OR(M30="",M30<0),$AD$3,M30) -> 1636081 | O30: 210920 | P30: 19.1 | Q30: 24 | R30: Agriculture | S30: =IF(R30="", "Unknown", R30) -> Agriculture | T30: 809 | U30: =IF(OR(T30="",T30>999),$AD$2,T30) -> 809 | V30: 5 | W30: Charged Off | X30: 2023-11-06 | Y30: =IF(ISNUMBER(X30), X30, DATEVALUE(X30)) -> 45236 | Z30: 0.1289
A31: LN-00288 | B31: =IF(A31="", "MISSING", "OK") -> OK | C31: Janet Johnson | D31: 56 | E31: =IF(OR(D31<18, D31>100),AD30,D31) -> 56 | F31: Female | G31: =IF(F31="", "Unknown", IF(OR(F31="F", F31="FEMALE", F31="Female"), "Female", IF(OR(F31="M", F31="MALE", F31="Male"), "Male", "Other"))) -> Female | H31: Machakos | I31: Employed | K31: =IF(I31="", "Unknown", I31) -> Employed | L31: 18 | M31: 1103780 | N31: =IF(OR(M31="",M31<0),$AD$3,M31) -> 1103780 | O31: 515164 | P31: 25.72 | Q31: 36 | R31: Home Improvement | S31: =IF(R31="", "Unknown", R31) -> Home Improvement | T31: 464 | U31: =IF(OR(T31="",T31>999),$AD$2,T31) -> 464 | V31: 4 | W31: Fully Paid | X31: 2020-04-13 | Y31: =IF(ISNUMBER(X31), X31, DATEVALUE(X31)) -> 43934 | Z31: 0.4667
A32: LN-01415 | B32: =IF(A32="", "MISSING", "OK") -> OK | C32: Samuel Smith | D32: 54 | E32: =IF(OR(D32<18, D32>100),AD31,D32) -> 54 | F32: Male | G32: =IF(F32="", "Unknown", IF(OR(F32="F", F32="FEMALE", F32="Female"), "Female", IF(OR(F32="M", F32="MALE", F32="Male"), "Male", "Other"))) -> Male | H32: Meru | I32: Employed | K32: =IF(I32="", "Unknown", I32) -> Employed | L32: 3 | M32: 601280 | N32: =IF(OR(M32="",M32<0),$AD$3,M32) -> 601280 | O32: 797635 | P32: 22.13 | Q32: 24 | R32: Agriculture | S32: =IF(R32="", "Unknown", R32) -> Agriculture | T32: 849 | U32: =IF(OR(T32="",T32>999),$AD$2,T32) -> 849 | V32: 2 | W32: Default | X32: 11-14-2023 | Y32: =IF(ISNUMBER(X32), X32, DATEVALUE(X32)) -> 45244 | Z32: 1.3266
A33: LN-00468 | B33: =IF(A33="", "MISSING", "OK") -> OK | C33: Joseph Cortez MD | D33: 47 | E33: =IF(OR(D33<18, D33>100),AD32,D33) -> 47 | F33: Female | G33: =IF(F33="", "Unknown", IF(OR(F33="F", F33="FEMALE", F33="Female"), "Female", IF(OR(F33="M", F33="MALE", F33="Male"), "Male", "Other"))) -> Female | H33: Thika | I33: Employed | K33: =IF(I33="", "Unknown", I33) -> Employed | L33: 17 | M33: 691083 | N33: =IF(OR(M33="",M33<0),$AD$3,M33) -> 691083 | O33: 396087 | P33: 25.31 | Q33: 12 | R33: Agriculture | S33: =IF(R33="", "Unknown", R33) -> Agriculture | T33: 449 | U33: =IF(OR(T33="",T33>999),$AD$2,T33) -> 449 | V33: 6 | W33: Late (61-90 days) | X33: 2023-10-03 | Y33: =IF(ISNUMBER(X33), X33, DATEVALUE(X33)) -> 45202 | Z33: 0.5731
A34: LN-00448 | B34: =IF(A34="", "MISSING", "OK") -> OK | C34: Richard Gonzalez | D34: 50 | E34: =IF(OR(D34<18, D34>100),AD33,D34) -> 50 | F34: Female | G34: =IF(F34="", "Unknown", IF(OR(F34="F", F34="FEMALE", F34="Female"), "Female", IF(OR(F34="M", F34="MALE", F34="Male"), "Male", "Other"))) -> Female | H34: Nairobi | I34: Business Owner | K34: =IF(I34="", "Unknown", I34) -> Business Owner | L34: 6 | M34: 746956 | N34: =IF(OR(M34="",M34<0),$AD$3,M34) -> 746956 | O34: 407699 | P34: 16.22 | Q34: 12 | R34: Agriculture | S34: =IF(R34="", "Unknown", R34) -> Agriculture | T34: 725 | U34: =IF(OR(T34="",T34>999),$AD$2,T34) -> 725 | V34: 6 | W34: current | X34: 2020-03-22 | Y34: =IF(ISNUMBER(X34), X34, DATEVALUE(X34)) -> 43912 | Z34: 0.5458
A35: LN-01117 | B35: =IF(A35="", "MISSING", "OK") -> OK | C35: Steven Hernandez | D35: 27 | E35: =IF(OR(D35<18, D35>100),AD34,D35) -> 27 | F35: Male | G35: =IF(F35="", "Unknown", IF(OR(F35="F", F35="FEMALE", F35="Female"), "Female", IF(OR(F35="M", F35="MALE", F35="Male"), "Male", "Other"))) -> Male | H35: Nairobi | I35: Employed | K35: =IF(I35="", "Unknown", I35) -> Employed | L35: 28 | M35: 656513 | N35: =IF(OR(M35="",M35<0),$AD$3,M35) -> 656513 | O35: 83972 | P35: 23.04 | Q35: 48 | R35: Business | S35: =IF(R35="", "Unknown", R35) -> Business | T35: 681 | U35: =IF(OR(T35="",T35>999),$AD$2,T35) -> 681 | V35: 6 | W35: Default | X35: 2021-04-05 | Y35: =IF(ISNUMBER(X35), X35, DATEVALUE(X35)) -> 44291 | Z35: 0.1279
A36: LN-01028 | B36: =IF(A36="", "MISSING", "OK") -> OK | C36: Scott Pham | D36: 58 | E36: =IF(OR(D36<18, D36>100),AD35,D36) -> 58 | F36: Female | G36: =IF(F36="", "Unknown", IF(OR(F36="F", F36="FEMALE", F36="Female"), "Female", IF(OR(F36="M", F36="MALE", F36="Male"), "Male", "Other"))) -> Female | H36: Machakos | I36: Business Owner | K36: =IF(I36="", "Unknown", I36) -> Business Owner | L36: 11 | M36: -551616 | N36: =IF(OR(M36="",M36<0),$AD$3,M36) -> 1333224 | O36: 686015 | P36: 26.9 | Q36: 48 | R36: Home Improvement | S36: =IF(R36="", "Unknown", R36) -> Home Improvement | T36: 628 | U36: =IF(OR(T36="",T36>999),$AD$2,T36) -> 628 | V36: 1 | W36: Charged Off | X36: 2023-05-09 | Y36: =IF(ISNUMBER(X36), X36, DATEVALUE(X36)) -> 45055 | Z36: 1.2436
A37: LN-00637 | B37: =IF(A37="", "MISSING", "OK") -> OK | C37: Matthew Salazar | D37: 23 | E37: =IF(OR(D37<18, D37>100),AD36,D37) -> 23 | F37: Female | G37: =IF(F37="", "Unknown", IF(OR(F37="F", F37="FEMALE", F37="Female"), "Female", IF(OR(F37="M", F37="MALE", F37="Male"), "Male", "Other"))) -> Female | H37: Nyeri | I37: Employed | K37: =IF(I37="", "Unknown", I37) -> Employed | L37: 5 | M37: 1724613 | N37: =IF(OR(M37="",M37<0),$AD$3,M37) -> 1724613 | O37: 425105 | P37: 26.23 | Q37: 12 | R37: Business | S37: =IF(R37="", "Unknown", R37) -> Business | T37: 596 | U37: =IF(OR(T37="",T37>999),$AD$2,T37) -> 596 | V37: 7 | W37: Late (31-60 days) | X37: 2022-08-30 | Y37: =IF(ISNUMBER(X37), X37, DATEVALUE(X37)) -> 44803 | Z37: 0.2465
A38: LN-00075 | B38: =IF(A38="", "MISSING", "OK") -> OK | C38: Susan Taylor | D38: 34 | E38: =IF(OR(D38<18, D38>100),AD37,D38) -> 34 | F38: male | G38: =IF(F38="", "Unknown", IF(OR(F38="F", F38="FEMALE", F38="Female"), "Female", IF(OR(F38="M", F38="MALE", F38="Male"), "Male", "Other"))) -> Male | H38: Kakamega | I38: Employed | K38: =IF(I38="", "Unknown", I38) -> Employed | L38: 14 | M38: 777897 | N38: =IF(OR(M38="",M38<0),$AD$3,M38) -> 777897 | O38: 411858 | P38: 8.99 | Q38: 24 | R38: Home Improvement | S38: =IF(R38="", "Unknown", R38) -> Home Improvement | T38: 552 | U38: =IF(OR(T38="",T38>999),$AD$2,T38) -> 552 | V38: 2 | W38: Current | X38: 2022-01-17 | Y38: =IF(ISNUMBER(X38), X38, DATEVALUE(X38)) -> 44578 | Z38: 0.5295
A39: LN-01481 | B39: =IF(A39="", "MISSING", "OK") -> OK | C39: Megan Franklin | D39: 38 | E39: =IF(OR(D39<18, D39>100),AD38,D39) -> 38 | F39: Female | G39: =IF(F39="", "Unknown", IF(OR(F39="F", F39="FEMALE", F39="Female"), "Female", IF(OR(F39="M", F39="MALE", F39="Male"), "Male", "Other"))) -> Female | H39: Mombasa | I39: Business Owner | K39: =IF(I39="", "Unknown", I39) -> Business Owner | L39: 10 | M39: 2287359 | N39: =IF(OR(M39="",M39<0),$AD$3,M39) -> 2287359 | O39: 550875 | P39: 12.73 | Q39: 36 | R39: Personal | S39: =IF(R39="", "Unknown", R39) -> Personal | T39: 714 | U39: =IF(OR(T39="",T39>999),$AD$2,T39) -> 714 | V39: 6 | W39: Late (31-60 days) | X39: 2022-09-02 | Y39: =IF(ISNUMBER(X39), X39, DATEVALUE(X39)) -> 44806 | Z39: 0.2408
A40: LN-00043 | B40: =IF(A40="", "MISSING", "OK") -> OK | C40: Timothy Jacobson | D40: 24 | E40: =IF(OR(D40<18, D40>100),AD39,D40) -> 24 | F40: Male | G40: =IF(F40="", "Unknown", IF(OR(F40="F", F40="FEMALE", F40="Female"), "Female", IF(OR(F40="M", F40="MALE", F40="Male"), "Male", "Other"))) -> Male | H40: Mombasa | I40: Unemployed | K40: =IF(I40="", "Unknown", I40) -> Unemployed | L40: 16 | M40: 228874 | N40: =IF(OR(M40="",M40<0),$AD$3,M40) -> 228874 | O40: 289160 | P40: 12.15 | Q40: 36 | S40: =IF(R40="", "Unknown", R40) -> Unknown | T40: 460 | U40: =IF(OR(T40="",T40>999),$AD$2,T40) -> 460 | V40: 5 | W40: Late (61-90 days) | X40: 2022-02-17 | Y40: =IF(ISNUMBER(X40), X40, DATEVALUE(X40)) -> 44609 | Z40: 1.2634
...

Sheet Data_Quality_Doc
A1: Data Quality Issues | B1: Number of Records | C1: Action Taken When Cleaning | D1: Reason
A2: Blank Loan_IDs | B2: =COUNTBLANK(Loan_Data!A2:A1517) -> 10 | C2: Delete all 10 rows | D2: LOAN ID is the primary key. Without it, records can't be ID'd, linked, or tracked
A3: Abnormal Ages(<18, >100) | B3: =COUNTIFS(Loan_Data!C2:C1517, "<18") + COUNTIFS(Loan_Data!C2:C1517, ">100") -> 10 | C3: Replaced with median age(44) | D3: Median is resistant to that distortion and gives you the "typical" borrower age
A4: Negative Annual Incomes | B4: =COUNTIF(Loan_Data!H2:H1517, "<0") -> 14 | C4: Replaced with median annual income | D4: Income cannot be negative. Treated it as an error.
A5: Inconsistent Casings(Gender) | B5: F, FEMALE, Female, M, Male | C5: Standardised casing to Male/Female | D5: Helps when it comes to gender analysis
A6: Blank Gender | B6: =COUNTBLANK(Loan_Data!D2:D1517) -> 38 | C6: Added Other to gender - maybe didn't want to disclose gender
A7: Blank Employment Status | B7: =COUNTBLANK(Loan_Data!F2:F1517) -> 31 | C7: Added Unknown to blank ones | D7: Employment status/income directly affects creditworthiness assessment and wrong imputation would distort analysis
A8: Blank Annual Income | B8: =COUNTBLANK(Loan_Data!H2:H1517) -> 49 | C8: Replaced with calculated median annual income
A9: Blank Loan Purpose | B9: =COUNTBLANK(Loan_Data!L2:L1517) -> 58 | C9: Replaced with unknown
A10: Blank Credit Score | B10: =COUNTBLANK(Loan_Data!M2:M1517) -> 55 | C10: Replaced with calculated median credit score
A11: Mixed Date Formats | B11: YYYY-MM-DD | C11: Formated column as a date, chose YYYY-MM-DD | D11: Compatible with most databases
B12: MM-DD-YYYY
B13: DD MON YYYY
